import { createContext, useContext, useEffect, useState } from 'react';
import { supabase } from '@/lib/supabase';
import { User, AuthError } from '@supabase/supabase-js';

interface AuthContextType {
  user: User | null;
  loading: boolean;
  signUp: (email: string, password: string, name: string) => Promise<void>;
  signIn: (email: string, password: string) => Promise<void>;
  signOut: () => Promise<void>;
}

const AuthContext = createContext<AuthContextType | undefined>(undefined);

export function AuthProvider({ children }: { children: React.ReactNode }) {
  const [user, setUser] = useState<User | null>(null);
  const [loading, setLoading] = useState(true);

  useEffect(() => {
    // Initialize the session
    const initSession = async () => {
      try {
        const { data: { session } } = await supabase.auth.getSession();
        setUser(session?.user ?? null);
      } catch (error) {
        console.error('Error initializing session:', error);
      } finally {
        setLoading(false);
      }
    };

    initSession();

    // Listen for auth state changes
    const { data: { subscription } } = supabase.auth.onAuthStateChange(async (_event, session) => {
      setUser(session?.user ?? null);
      setLoading(false);
    });

    return () => {
      subscription.unsubscribe();
    };
  }, []);

  const signUp = async (email: string, password: string, name: string) => {
    try {
      const { error } = await supabase.auth.signUp({
        email,
        password,
        options: {
          data: {
            name,
          },
        },
      });
      if (error) throw error;
    } catch (error) {
      if (error instanceof AuthError) {
        throw error;
      }
      throw new Error('An unexpected error occurred during sign up');
    }
  };

  const signIn = async (email: string, password: string) => {
    try {
      const { error } = await supabase.auth.signInWithPassword({
        email,
        password,
      });
      if (error) throw error;
    } catch (error) {
      if (error instanceof AuthError) {
        throw error;
      }
      throw new Error('An unexpected error occurred during sign in');
    }
  };

  const signOut = async () => {
    try {
      const { error } = await supabase.auth.signOut();
      if (error) throw error;
    } catch (error) {
      if (error instanceof AuthError) {
        throw error;
      }
      throw new Error('An unexpected error occurred during sign out');
    }
  };

  return (
    <AuthContext.Provider value={{ user, loading, signUp, signIn, signOut }}>
      {children}
    </AuthContext.Provider>
  );
}

export const useAuth = () => {
  const context = useContext(AuthContext);
  if (context === undefined) {
    throw new Error('useAuth must be used within an AuthProvider');
  }
  return context;
};